Workbook
Name tt_Type: LISTS!$B$7:$B$14
Name tt_Dir: LISTS!$C$7:$C$14
Name tt_Src: LISTS!$D$7:$D$14
Name tt_Tax: LISTS!$E$7:$E$14
Name tt_Other: LISTS!$G$7:$G$14
Name lstTypes: LISTS!$B$7:$B$14
Name acctAR: LISTS!$K$7
Name acctAP: LISTS!$K$8
Name acctTax: LISTS!$K$9
Name acctCapital: LISTS!$K$10
Name acctDrawings: LISTS!$K$11
Name acctOBE: LISTS!$K$12
Name sys_Role: LISTS!$I$7:$I$12
Name sys_Acct: LISTS!$K$7:$K$12
Name sys_Check: LISTS!$L$7:$L$12
Name at_Type: LISTS!$N$7:$N$16
Name at_Stmt: LISTS!$O$7:$O$16
Name at_Sign: LISTS!$P$7:$P$16
Name at_Normal: LISTS!$Q$7:$Q$16
Name at_Section: LISTS!$R$7:$R$16
Name lstPayMethods: LISTS!$B$21:$B$35
Name lstBizTypes: LISTS!$C$21:$C$32
Name lstMonths: LISTS!$D$21:$D$32
Name lstYesNo: LISTS!$E$21:$E$22
Name lstCF: LISTS!$F$21:$F$24
Name lstNormal: LISTS!$G$21:$G$22
Name lstBuckets: LISTS!$H$21:$H$25
Name lstPayAccts: LISTS!$J$21:$J$50
Name lstAccounts: LISTS!$K$21:$K$170
Name BizName: SETUP!$C$6
Name BizType: SETUP!$C$7
Name OwnerName: SETUP!$C$8
Name BizAddress: SETUP!$C$9
Name BizEmail: SETUP!$C$10
Name BizPhone: SETUP!$C$11
Name StartDate: SETUP!$C$14
Name FYStartMonthName: SETUP!$C$15
Name Currency: SETUP!$C$16
Name OpenCash: SETUP!$C$17
Name OpenBank: SETUP!$C$18
Name DefaultTerms: SETUP!$C$19
Name TaxOn: SETUP!$C$22
Name TaxLabel: SETUP!$C$23
Name RptYear: SETUP!$C$26
Name RptMonth: SETUP!$C$27
Name RptStart: SETUP!$C$28
Name AsOf: SETUP!$C$29
Name FYStartMonth: SETUP!$C$30
Name FYStart: SETUP!$C$31
Name FYEnd: SETUP!$C$32
Name FYYM: SETUP!$C$33
Name RptIdx: SETUP!$C$34
Name PrevStart: SETUP!$C$35
Name PrevEnd: SETUP!$C$36
Name TermsDays: SETUP!$C$37
Name coa_Code: COA!$B$7:$B$156
Name coa_Name: COA!$C$7:$C$156
Name coa_Type: COA!$D$7:$D$156
Name coa_Normal: COA!$E$7:$E$156
Name coa_CF: COA!$F$7:$F$156

Sheet START_HERE
B2: SimpleLedger
B3: Small Business Accounting Workbook
B4: Know where your money goes, know how much you earn, and understand your business finances from one simple Excel workbook.
B5: ="Workbook for: "&BizName
B8: QUICK START
B9: =HYPERLINK("#SETUP!A1","1 · Setup") | C9: =HYPERLINK("#TRANSACTIONS!A1","2 · Record") | D9: =HYPERLINK("#DASHBOARD!A1","3 · Dashboard") | E9: =HYPERLINK("#PNL!A1","Profit & Loss") | F9: =HYPERLINK("#BALANCE_SHEET!A1","Balance Sheet") | G9: =HYPERLINK("#CASH_FLOW!A1","Cash Flow") | H9: =HYPERLINK("#HELP!A1","Help")
B10: =HYPERLINK("#AR!A1","Invoices (AR)") | C10: =HYPERLINK("#AP!A1","Bills (AP)") | D10: =HYPERLINK("#CUSTOMERS!A1","Customers") | E10: =HYPERLINK("#VENDORS!A1","Vendors") | F10: =HYPERLINK("#COA!A1","Accounts") | G10: =HYPERLINK("#MONTHLY_SUMMARY!A1","Monthly") | H10: =HYPERLINK("#LEDGER!A1","Ledger")
B12: YOUR WORKFLOW
B13: 1. Read this page | D13: Two minutes. It tells you where everything is.
B14: 2. Complete SETUP | D14: Business name, start date, currency, beginning cash and bank balances.
B15: 3. Add customers and vendors | D15: Optional but recommended: CUSTOMERS and VENDORS sheets.
B16: 4. Record transactions | D16: Every sale, expense, payment and transfer — one row each on TRANSACTIONS.
B17: 5. Record credit sales and unpaid bills | D17: Invoices you will be paid for later → AR. Bills you will pay later → AP.
B18: 6. Review the DASHBOARD | D18: Pick the month at the top. Revenue, expenses, profit and cash update automatically.
B19: 7. Review monthly reports | D19: Profit & Loss, Balance Sheet, Cash Flow, Monthly Summary.
B20: 8. Fix warnings | D20: The Dashboard's Data Health box lists anything that needs attention (⛔ / ⚠).
B21: 9. Export / share | D21: File → Print or Save as PDF on any report sheet. Reports are print-ready.
B23: COLOUR GUIDE
B24: Yellow cell | C24: A setting you fill in (SETUP, LISTS, report filters).
B25: White table column | C25: Where you type your data (dark-blue header).
B26: Grey cell / column | C26: Automatic. Calculated for you — do not type here.
B27: ⛔ Error | C27: The row is NOT included in reports until you fix it.
B28: ⚠ Warning | C28: Included in reports, but please double-check.
B29: ✓ OK | C29: All good.
B31: GOOD TO KNOW
B32: • Everything is calculated from three input sheets: TRANSACTIONS, AR and AP. Reports never need typing.
B33: • No accounting knowledge needed: choose a Type (Money In / Money Out …) and a Category. Debits and credits are automatic.
B34: • Don't delete or rename sheets. Don't type over grey cells. Most report sheets are protected (no password) to prevent accidents.
B35: • Capacity: 2,000 transactions, 500 invoices and 500 bills per workbook — plenty for a typical small business year. Start a fresh copy each fiscal year.
B36: • Keep a backup: save a dated copy at the end of every month (e.g. Books-2026-09.xlsx).
B37: • Requires Microsoft Excel 2010 or later (Windows or Mac) or Microsoft 365. No macros.
B39: SimpleLedger v1.0.0

Sheet SETUP
B1: Setup
B2: Fill in the yellow cells once. Everything else in the workbook reads from here.
B5: BUSINESS DETAILS
B6: Business name | C6: Sunrise Bakery & Café | D6: Shown on every report header.
B7: Business type | C7: Food & Beverage | D7: Pick the closest match.
B8: Owner name | C8: Maria Santos
B9: Business address | C9: 123 Mabini St., Quezon City
B10: Email | C10: hello@sunrisebakery.example
B11: Phone | C11: 0917 555 0100
B13: ACCOUNTING SETTINGS
B14: Accounting start date | C14: 46023 | D14: The day you start recording in this workbook. Opening balances are as of this date.
B15: Fiscal year starts in | C15: January | D15: Most small businesses use January (calendar year).
B16: Currency (code or symbol) | C16: PHP | D16: Used in report headings, e.g. PHP, USD, ₱, $.
B17: Beginning cash on hand | C17: 15000 | D17: Cash you physically had on the start date. Posts to 'Cash on Hand'.
B18: Beginning bank balance | C18: 285000 | D18: Bank balance on the start date. Posts to 'Bank Account'. Other opening balances: COA sheet.
B19: Default payment terms (days) | C19: 30 | D19: Used for invoice/bill due dates when you leave Due Date blank.
B21: TAX SETTINGS
B22: Track VAT / sales tax separately? | C22: Yes | D22: Yes = the Tax column is posted to the Tax Payable account. No = tax columns are ignored.
B23: Tax name | C23: VAT | D23: e.g. VAT, GST, Sales Tax. Used in labels only.
B25: REPORT PERIOD (automatic — choose the month on the Dashboard) | D25: =HYPERLINK("#DASHBOARD!C5","→ Change report month on the Dashboard")
B26: Report year | C26: =IF(ISNUMBER(RptYearIn),RptYearIn,YEAR(TODAY()))
B27: Report month (1-12) | C27: =IFERROR(MATCH(RptMonthIn,lstMonths,0),MONTH(TODAY()))
B28: Report period start | C28: =DATE(RptYear,RptMonth,1)
B29: Report period end (as-of date) | C29: =EOMONTH(RptStart,0)
B30: Fiscal year start month (1-12) | C30: =IFERROR(MATCH(FYStartMonthName,lstMonths,0),1)
B31: Fiscal year start | C31: =DATE(RptYear-IF(RptMonth<FYStartMonth,1,0),FYStartMonth,1)
B32: Fiscal year end | C32: =EDATE(FYStart,12)-1
B33: Fiscal year start (year*12+month) | C33: =YEAR(FYStart)*12+MONTH(FYStart)
B34: Report month number within fiscal year | C34: =YEAR(RptStart)*12+MONTH(RptStart)-FYYM+1
B35: Previous month start | C35: =EDATE(RptStart,-1)
B36: Previous month end | C36: =RptStart-1
B37: Default terms used | C37: =IF(ISNUMBER(DefaultTerms),DefaultTerms,30)

Sheet DASHBOARD
B1: Financial Dashboard | P1: Chart data (automatic)
B2: =BizName
P3: Month | Q3: Revenue | R3: Expenses | S3: Net Profit
P4: =MONTHLY_SUMMARY!B7 | Q4: =MONTHLY_SUMMARY!C7 | R4: =MONTHLY_SUMMARY!C7-MONTHLY_SUMMARY!H7 | S4: =MONTHLY_SUMMARY!H7
B5: Report month | C5: September | E5: Year | F5: 2026 | H5: ="Period: "&TEXT(RptStart,"mmmm yyyy")&" · Year to date from "&TEXT(FYStart,"dd mmm yyyy")&" · "&Currency | P5: =MONTHLY_SUMMARY!B8 | Q5: =MONTHLY_SUMMARY!C8 | R5: =MONTHLY_SUMMARY!C8-MONTHLY_SUMMARY!H8 | S5: =MONTHLY_SUMMARY!H8
P6: =MONTHLY_SUMMARY!B9 | Q6: =MONTHLY_SUMMARY!C9 | R6: =MONTHLY_SUMMARY!C9-MONTHLY_SUMMARY!H9 | S6: =MONTHLY_SUMMARY!H9
B7: REVENUE · THIS MONTH | E7: EXPENSES · THIS MONTH | H7: NET PROFIT · THIS MONTH | K7: CASH BALANCE · MONTH END | P7: =MONTHLY_SUMMARY!B10 | Q7: =MONTHLY_SUMMARY!C10 | R7: =MONTHLY_SUMMARY!C10-MONTHLY_SUMMARY!H10 | S7: =MONTHLY_SUMMARY!H10
B8: =PL_Rev_Cur | E8: =PL_COS_Cur+PL_Opex_Cur+PL_OthExp_Cur | H8: =PL_Net_Cur | K8: =CF_End_Cur | P8: =MONTHLY_SUMMARY!B11 | Q8: =MONTHLY_SUMMARY!C11 | R8: =MONTHLY_SUMMARY!C11-MONTHLY_SUMMARY!H11 | S8: =MONTHLY_SUMMARY!H11
B9: ="Year to date: "&TEXT(PL_Rev_YTD,"#,##0") | E9: ="Year to date: "&TEXT(PL_COS_YTD+PL_Opex_YTD+PL_OthExp_YTD,"#,##0") | H9: ="Year to date: "&TEXT(PL_Net_YTD,"#,##0;(#,##0)") | K9: ="Change this month: "&TEXT(CF_Net_Cur,"+#,##0;-#,##0;0") | P9: =MONTHLY_SUMMARY!B12 | Q9: =MONTHLY_SUMMARY!C12 | R9: =MONTHLY_SUMMARY!C12-MONTHLY_SUMMARY!H12 | S9: =MONTHLY_SUMMARY!H12
P10: =MONTHLY_SUMMARY!B13 | Q10: =MONTHLY_SUMMARY!C13 | R10: =MONTHLY_SUMMARY!C13-MONTHLY_SUMMARY!H13 | S10: =MONTHLY_SUMMARY!H13
B11: RECEIVABLES · CUSTOMERS OWE YOU | E11: PAYABLES · YOU OWE SUPPLIERS | H11: GROSS MARGIN · YEAR TO DATE | K11: NET MARGIN · YEAR TO DATE | P11: =MONTHLY_SUMMARY!B14 | Q11: =MONTHLY_SUMMARY!C14 | R11: =MONTHLY_SUMMARY!C14-MONTHLY_SUMMARY!H14 | S11: =MONTHLY_SUMMARY!H14
B12: =SUMIFS(calc_Bal,calc_Name,acctAR) | E12: =-SUMIFS(calc_Bal,calc_Name,acctAP) | H12: =IF(PL_GM_YTD="","",PL_GM_YTD) | K12: =IF(PL_NM_YTD="","",PL_NM_YTD) | P12: =MONTHLY_SUMMARY!B15 | Q12: =MONTHLY_SUMMARY!C15 | R12: =MONTHLY_SUMMARY!C15-MONTHLY_SUMMARY!H15 | S12: =MONTHLY_SUMMARY!H15
B13: ="Overdue: "&TEXT(SUMIFS(ar_Balance,ar_Status,"Overdue"),"#,##0") | E13: ="Overdue: "&TEXT(SUMIFS(ap_Balance,ap_Status,"Overdue"),"#,##0") | H13: ="This month: "&IF(PL_GM_Cur="","-",TEXT(PL_GM_Cur,"0.0%")) | K13: ="This month: "&IF(PL_NM_Cur="","-",TEXT(PL_NM_Cur,"0.0%")) | P13: =MONTHLY_SUMMARY!B16 | Q13: =MONTHLY_SUMMARY!C16 | R13: =MONTHLY_SUMMARY!C16-MONTHLY_SUMMARY!H16 | S13: =MONTHLY_SUMMARY!H16
P14: =MONTHLY_SUMMARY!B17 | Q14: =MONTHLY_SUMMARY!C17 | R14: =MONTHLY_SUMMARY!C17-MONTHLY_SUMMARY!H17 | S14: =MONTHLY_SUMMARY!H17
B15: DATA HEALTH | P15: =MONTHLY_SUMMARY!B18 | Q15: =MONTHLY_SUMMARY!C18 | R15: =MONTHLY_SUMMARY!C18-MONTHLY_SUMMARY!H18 | S15: =MONTHLY_SUMMARY!H18
B16: Trial balance | D16: =TB_Status | H16: Entries with warnings | J16: =IF(COUNTIF(tx_Warn,"?*")+COUNTIF(ar_Warn,"?*")+COUNTIF(ap_Warn,"?*")=0,"✓ None","⚠ "&COUNTIF(tx_Warn,"?*")+COUNTIF(ar_Warn,"?*")+COUNTIF(ap_Warn,"?*")&" to review")
B17: Balance sheet | D17: =IF(BS_Diff=0,"✓ Balanced","⚠ Out of balance by "&TEXT(BS_Diff,"#,##0.00")) | H17: Receivables register | J17: =IF(ROUND(SUM(ar_Balance)-SUMIFS(calc_Bal,calc_Name,acctAR),2)=0,"✓ Matches the ledger","⚠ Differs from ledger by "&TEXT(SUM(ar_Balance)-SUMIFS(calc_Bal,calc_Name,acctAR),"#,##0.00")) | P17: Top expenses (YTD) | Q17: Amount
B18: Cash flow | D18: =IF(LEFT(CF_Status,1)="✓","✓ Reconciles","⚠ Does not reconcile") | H18: Payables register | J18: =IF(ROUND(SUM(ap_Balance)-(-SUMIFS(calc_Bal,calc_Name,acctAP)),2)=0,"✓ Matches the ledger","⚠ Differs from ledger by "&TEXT(SUM(ap_Balance)-(-SUMIFS(calc_Bal,calc_Name,acctAP)),"#,##0.00")) | P18: =IFERROR(INDEX(calc_Name,MATCH(LARGE(calc_TopKey,1),calc_TopKey,0)),"") | Q18: =IF(P18="",0,INDEX(calc_YTD,MATCH(P18,calc_Name,0)))
B19: Entries with errors | D19: =IF(COUNTIF(tx_Err,"?*")+COUNTIF(ar_Err,"?*")+COUNTIF(ap_Err,"?*")=0,"✓ None","⛔ "&COUNTIF(tx_Err,"?*")+COUNTIF(ar_Err,"?*")+COUNTIF(ap_Err,"?*")&" not posted — see the Check column") | H19: Setup | J19: =IF(COUNTIF(sys_Check,"⛔*")+COUNTIF(coa_Check,"⛔*")>0,"⛔ Fix the Chart of Accounts / Lists",IF(COUNT(tx_Date)>1800,"⚠ Transactions sheet is nearly full","✓ OK")) | P19: =IFERROR(INDEX(calc_Name,MATCH(LARGE(calc_TopKey,2),calc_TopKey,0)),"") | Q19: =IF(P19="",0,INDEX(calc_YTD,MATCH(P19,calc_Name,0)))
P20: =IFERROR(INDEX(calc_Name,MATCH(LARGE(calc_TopKey,3),calc_TopKey,0)),"") | Q20: =IF(P20="",0,INDEX(calc_YTD,MATCH(P20,calc_Name,0)))
P21: =IFERROR(INDEX(calc_Name,MATCH(LARGE(calc_TopKey,4),calc_TopKey,0)),"") | Q21: =IF(P21="",0,INDEX(calc_YTD,MATCH(P21,calc_Name,0)))
P22: =IFERROR(INDEX(calc_Name,MATCH(LARGE(calc_TopKey,5),calc_TopKey,0)),"") | Q22: =IF(P22="",0,INDEX(calc_YTD,MATCH(P22,calc_Name,0)))
P24: Aging (days overdue) | Q24: Receivables | R24: Payables
P25: Current | Q25: =SUMIFS(ar_Balance,ar_Bucket,P25) | R25: =SUMIFS(ap_Balance,ap_Bucket,P25)
P26: 1-30 | Q26: =SUMIFS(ar_Balance,ar_Bucket,P26) | R26: =SUMIFS(ap_Balance,ap_Bucket,P26)
P27: 31-60 | Q27: =SUMIFS(ar_Balance,ar_Bucket,P27) | R27: =SUMIFS(ap_Balance,ap_Bucket,P27)
P28: 61-90 | Q28: =SUMIFS(ar_Balance,ar_Bucket,P28) | R28: =SUMIFS(ap_Balance,ap_Bucket,P28)
P29: 90+ | Q29: =SUMIFS(ar_Balance,ar_Bucket,P29) | R29: =SUMIFS(ap_Balance,ap_Bucket,P29)
B54: CASH FLOW · THIS MONTH | H54: WHO OWES WHOM
B55: Cash at start of month | E55: =CF_Begin_Cur | H55: Receivables due in the next 14 days | L55: =SUMIFS(ar_Balance,ar_EffDue,">="&AsOf,ar_EffDue,"<="&(AsOf+14))
B56: + Operating activities | E56: =CF_Op_Cur | H56: Payables due in the next 14 days | L56: =SUMIFS(ap_Balance,ap_EffDue,">="&AsOf,ap_EffDue,"<="&(AsOf+14))
B57: + Investing activities | E57: =CF_Inv_Cur
B58: + Financing activities | E58: =CF_Fin_Cur | H58: Top customers owing you | K58: Top vendors you owe
B59: Cash at end of month | E59: =CF_End_Cur | H59: =IFERROR(INDEX(cust_Name,MATCH(LARGE(cust_TopKey,1),cust_TopKey,0)),"") | J59: =IF(H59="","",INDEX(cust_Outstanding,MATCH(H59,cust_Name,0))) | K59: =IFERROR(INDEX(vend_Name,MATCH(LARGE(vend_TopKey,1),vend_TopKey,0)),"") | M59: =IF(K59="","",INDEX(vend_Outstanding,MATCH(K59,vend_Name,0)))
H60: =IFERROR(INDEX(cust_Name,MATCH(LARGE(cust_TopKey,2),cust_TopKey,0)),"") | J60: =IF(H60="","",INDEX(cust_Outstanding,MATCH(H60,cust_Name,0))) | K60: =IFERROR(INDEX(vend_Name,MATCH(LARGE(vend_TopKey,2),vend_TopKey,0)),"") | M60: =IF(K60="","",INDEX(vend_Outstanding,MATCH(K60,vend_Name,0)))
H61: =IFERROR(INDEX(cust_Name,MATCH(LARGE(cust_TopKey,3),cust_TopKey,0)),"") | J61: =IF(H61="","",INDEX(cust_Outstanding,MATCH(H61,cust_Name,0))) | K61: =IFERROR(INDEX(vend_Name,MATCH(LARGE(vend_TopKey,3),vend_TopKey,0)),"") | M61: =IF(K61="","",INDEX(vend_Outstanding,MATCH(K61,vend_Name,0)))

Sheet TRANSACTIONS
B1: Transactions
B2: Record every money movement here: sales, expenses, payments, transfers. One row = one transaction. | H2: Example: 15-Jan-2026 | Money Out | Rent | Shop rent January | … | Bank Account | 15,000.00
B4: Tip: work top-to-bottom, one row per entry. Rows with ⛔ are NOT included in reports until fixed; ⚠ rows are included but worth a look.
B5: ▼ YOUR ENTRIES (white columns — type or pick from the dropdown) | O5: ▼ AUTOMATIC (grey columns — calculated, do not type)
B6: Transaction ID | C6: Date | D6: Type | E6: Category (Account) | F6: Description | G6: Customer | H6: Vendor | I6: Payment Method | J6: Reference No. / Invoice # / Bill # | K6: Paid From / Deposited To | L6: Amount (incl. tax) | M6: Tax | N6: Notes | O6: Net Amount | P6: Account Type | Q6: Debit Account | R6: Credit Account | S6: Check | T6: Blank? | U6: Direction | V6: Other side | W6: Tax used | X6: Error | Y6: Warning | Z6: Posted | AA6: Debit Amt | AB6: Credit Amt | AC6: Tax Debit | AD6: Tax Credit
B7: TX-0001 | C7: 46023 | D7: Money Out | E7: Rent | F7: Shop rent | I7: Bank Transfer | J7: RENT-01 | K7: Bank Account | L7: 28000 | M7: 3000 | O7: =IF(Z7=1,L7-W7,"") | P7: =IF(V7="","",IFERROR(INDEX(coa_Type,MATCH(V7,coa_Name,0)),"")) | Q7: =IF(Z7=1,IF(U7="In",K7&"",V7),"") | R7: =IF(Z7=1,IF(U7="In",V7,K7&""),"") | S7: =IF(X7<>"","⛔ "&X7&" — not posted",IF(Y7<>"","⚠ "&Y7,IF(Z7=1,"✓ OK",""))) | T7: =IF(AND(C7="",D7="",E7="",L7="",K7=""),1,0) | U7: =IFERROR(INDEX(tt_Dir,MATCH(D7,tt_Type,0)),"") | V7: =IF(D7="","",IFERROR(IF(INDEX(tt_Other,MATCH(D7,tt_Type,0))="",E7&"",INDEX(tt_Other,MATCH(D7,tt_Type,0))),"")) | W7: =IF(OR(TaxOn<>"Yes",NOT(ISNUMBER(M7))),0,IF(IFERROR(INDEX(tt_Tax,MATCH(D7,tt_Type,0)),"No")="Yes",M7,0)) | X7: =IF(T7=1,"",IF(C7="","Missing transaction date",IF(NOT(ISNUMBER(C7)),"Invalid date",IF(OR(C7<DATE(2000,1,1),C7>DATE(2099,12,31)),"Invalid date",IF(D7="","Select a type",IF(U7="","Unknown type: "&D7,IF(V7="","Select an account (Category)",IF(ISNA(MATCH(V7,coa_Name,0)),"Unknown account: "&V7,IF(K7="","Select Paid From / Deposited To",IF(ISNA(MATCH(K7,coa_Name,0)),"Unknown account: "&K7,IF(NOT(ISNUMBER(L7)),"Enter an amount",IF(L7=0,"Enter an amount",IF(ABS(W7)>ABS(L7),"Tax is larger than the amount",""))))))))))))) | Y7: =IF(OR(T7=1,X7<>""),"",IF(AND(B7<>"",COUNTIF(tx_ID,B7)>1),"Duplicate transaction ID",IF(AND(L7<0,D7<>"Adjustment"),"Negative amount — check this entry",IF(AND(D7="Customer Payment",G7=""),"Add the customer",IF(AND(D7="Customer Payment",OR(J7="",COUNTIF(ar_No,J7&"")=0)),"Invoice # in Reference not found on AR sheet",IF(AND(D7="Bill Payment",H7=""),"Add the vendor",IF(AND(D7="Bill Payment",OR(J7="",COUNTIFS(ap_No,J7&"",ap_Party,H7&"")=0)),"Bill # + vendor not found on AP sheet",IF(AND(ISNUMBER(M7),N(M7)<>0,W7=0),"Tax ignored (tax tracking off, or not allowed for this type)",IF(V7=K7&"","Same account on both sides",IF(AND(ISNUMBER(StartDate),C7<StartDate),"Date is before the accounting start date",IF(AND(D7<>"Adjustment",IFERROR(INDEX(coa_Pay,MATCH(K7&"",coa_Name,0)),"")<>"Yes"),"Paid From / Deposited To is not a payment account",""))))))))))) | Z7: =IF(AND(T7=0,X7=""),1,0) | AA7: =IF(Z7=1,IF(U7="In",L7,L7-W7),0) | AB7: =IF(Z7=1,IF(U7="In",L7-W7,L7),0) | AC7: =IF(AND(Z7=1,U7="Out"),W7,0) | AD7: =IF(AND(Z7=1,U7="In"),W7,0)
B8: TX-0002 | C8: 46026 | D8: Money In | E8: Product Sales | F8: Counter sales week 1 | I8: Cash | K8: Cash on Hand | L8: 43084.99 | M8: 4616.25 | O8: =IF(Z8=1,L8-W8,"") | P8: =IF(V8="","",IFERROR(INDEX(coa_Type,MATCH(V8,coa_Name,0)),"")) | Q8: =IF(Z8=1,IF(U8="In",K8&"",V8),"") | R8: =IF(Z8=1,IF(U8="In",V8,K8&""),"") | S8: =IF(X8<>"","⛔ "&X8&" — not posted",IF(Y8<>"","⚠ "&Y8,IF(Z8=1,"✓ OK",""))) | T8: =IF(AND(C8="",D8="",E8="",L8="",K8=""),1,0) | U8: =IFERROR(INDEX(tt_Dir,MATCH(D8,tt_Type,0)),"") | V8: =IF(D8="","",IFERROR(IF(INDEX(tt_Other,MATCH(D8,tt_Type,0))="",E8&"",INDEX(tt_Other,MATCH(D8,tt_Type,0))),"")) | W8: =IF(OR(TaxOn<>"Yes",NOT(ISNUMBER(M8))),0,IF(IFERROR(INDEX(tt_Tax,MATCH(D8,tt_Type,0)),"No")="Yes",M8,0)) | X8: =IF(T8=1,"",IF(C8="","Missing transaction date",IF(NOT(ISNUMBER(C8)),"Invalid date",IF(OR(C8<DATE(2000,1,1),C8>DATE(2099,12,31)),"Invalid date",IF(D8="","Select a type",IF(U8="","Unknown type: "&D8,IF(V8="","Select an account (Category)",IF(ISNA(MATCH(V8,coa_Name,0)),"Unknown account: "&V8,IF(K8="","Select Paid From / Deposited To",IF(ISNA(MATCH(K8,coa_Name,0)),"Unknown account: "&K8,IF(NOT(ISNUMBER(L8)),"Enter an amount",IF(L8=0,"Enter an amount",IF(ABS(W8)>ABS(L8),"Tax is larger than the amount",""))))))))))))) | Y8: =IF(OR(T8=1,X8<>""),"",IF(AND(B8<>"",COUNTIF(tx_ID,B8)>1),"Duplicate transaction ID",IF(AND(L8<0,D8<>"Adjustment"),"Negative amount — check this entry",IF(AND(D8="Customer Payment",G8=""),"Add the customer",IF(AND(D8="Customer Payment",OR(J8="",COUNTIF(ar_No,J8&"")=0)),"Invoice # in Reference not found on AR sheet",IF(AND(D8="Bill Payment",H8=""),"Add the vendor",IF(AND(D8="Bill Payment",OR(J8="",COUNTIFS(ap_No,J8&"",ap_Party,H8&"")=0)),"Bill # + vendor not found on AP sheet",IF(AND(ISNUMBER(M8),N(M8)<>0,W8=0),"Tax ignored (tax tracking off, or not allowed for this type)",IF(V8=K8&"","Same account on both sides",IF(AND(ISNUMBER(StartDate),C8<StartDate),"Date is before the accounting start date",IF(AND(D8<>"Adjustment",IFERROR(INDEX(coa_Pay,MATCH(K8&"",coa_Name,0)),"")<>"Yes"),"Paid From / Deposited To is not a payment account",""))))))))))) | Z8: =IF(AND(T8=0,X8=""),1,0) | AA8: =IF(Z8=1,IF(U8="In",L8,L8-W8),0) | AB8: =IF(Z8=1,IF(U8="In",L8-W8,L8),0) | AC8: =IF(AND(Z8=1,U8="Out"),W8,0) | AD8: =IF(AND(Z8=1,U8="In"),W8,0)
B9: TX-0003 | C9: 46027 | D9: Money In | E9: Product Sales | F9: GCash / online orders week 1 | I9: E-Wallet | K9: E-Wallet / Online Payments | L9: 16978.36 | M9: 1819.11 | O9: =IF(Z9=1,L9-W9,"") | P9: =IF(V9="","",IFERROR(INDEX(coa_Type,MATCH(V9,coa_Name,0)),"")) | Q9: =IF(Z9=1,IF(U9="In",K9&"",V9),"") | R9: =IF(Z9=1,IF(U9="In",V9,K9&""),"") | S9: =IF(X9<>"","⛔ "&X9&" — not posted",IF(Y9<>"","⚠ "&Y9,IF(Z9=1,"✓ OK",""))) | T9: =IF(AND(C9="",D9="",E9="",L9="",K9=""),1,0) | U9: =IFERROR(INDEX(tt_Dir,MATCH(D9,tt_Type,0)),"") | V9: =IF(D9="","",IFERROR(IF(INDEX(tt_Other,MATCH(D9,tt_Type,0))="",E9&"",INDEX(tt_Other,MATCH(D9,tt_Type,0))),"")) | W9: =IF(OR(TaxOn<>"Yes",NOT(ISNUMBER(M9))),0,IF(IFERROR(INDEX(tt_Tax,MATCH(D9,tt_Type,0)),"No")="Yes",M9,0)) | X9: =IF(T9=1,"",IF(C9="","Missing transaction date",IF(NOT(ISNUMBER(C9)),"Invalid date",IF(OR(C9<DATE(2000,1,1),C9>DATE(2099,12,31)),"Invalid date",IF(D9="","Select a type",IF(U9="","Unknown type: "&D9,IF(V9="","Select an account (Category)",IF(ISNA(MATCH(V9,coa_Name,0)),"Unknown account: "&V9,IF(K9="","Select Paid From / Deposited To",IF(ISNA(MATCH(K9,coa_Name,0)),"Unknown account: "&K9,IF(NOT(ISNUMBER(L9)),"Enter an amount",IF(L9=0,"Enter an amount",IF(ABS(W9)>ABS(L9),"Tax is larger than the amount",""))))))))))))) | Y9: =IF(OR(T9=1,X9<>""),"",IF(AND(B9<>"",COUNTIF(tx_ID,B9)>1),"Duplicate transaction ID",IF(AND(L9<0,D9<>"Adjustment"),"Negative amount — check this entry",IF(AND(D9="Customer Payment",G9=""),"Add the customer",IF(AND(D9="Customer Payment",OR(J9="",COUNTIF(ar_No,J9&"")=0)),"Invoice # in Reference not found on AR sheet",IF(AND(D9="Bill Payment",H9=""),"Add the vendor",IF(AND(D9="Bill Payment",OR(J9="",COUNTIFS(ap_No,J9&"",ap_Party,H9&"")=0)),"Bill # + vendor not found on AP sheet",IF(AND(ISNUMBER(M9),N(M9)<>0,W9=0),"Tax ignored (tax tracking off, or not allowed for this type)",IF(V9=K9&"","Same account on both sides",IF(AND(ISNUMBER(StartDate),C9<StartDate),"Date is before the accounting start date",IF(AND(D9<>"Adjustment",IFERROR(INDEX(coa_Pay,MATCH(K9&"",coa_Name,0)),"")<>"Yes"),"Paid From / Deposited To is not a payment account",""))))))))))) | Z9: =IF(AND(T9=0,X9=""),1,0) | AA9: =IF(Z9=1,IF(U9="In",L9,L9-W9),0) | AB9: =IF(Z9=1,IF(U9="In",L9-W9,L9),0) | AC9: =IF(AND(Z9=1,U9="Out"),W9,0) | AD9: =IF(AND(Z9=1,U9="In"),W9,0)
B10: TX-0004 | C10: 46028 | D10: Transfer | E10: Bank Account | F10: Cash deposit to bank | I10: Cash | K10: Cash on Hand | L10: 36600 | O10: =IF(Z10=1,L10-W10,"") | P10: =IF(V10="","",IFERROR(INDEX(coa_Type,MATCH(V10,coa_Name,0)),"")) | Q10: =IF(Z10=1,IF(U10="In",K10&"",V10),"") | R10: =IF(Z10=1,IF(U10="In",V10,K10&""),"") | S10: =IF(X10<>"","⛔ "&X10&" — not posted",IF(Y10<>"","⚠ "&Y10,IF(Z10=1,"✓ OK",""))) | T10: =IF(AND(C10="",D10="",E10="",L10="",K10=""),1,0) | U10: =IFERROR(INDEX(tt_Dir,MATCH(D10,tt_Type,0)),"") | V10: =IF(D10="","",IFERROR(IF(INDEX(tt_Other,MATCH(D10,tt_Type,0))="",E10&"",INDEX(tt_Other,MATCH(D10,tt_Type,0))),"")) | W10: =IF(OR(TaxOn<>"Yes",NOT(ISNUMBER(M10))),0,IF(IFERROR(INDEX(tt_Tax,MATCH(D10,tt_Type,0)),"No")="Yes",M10,0)) | X10: =IF(T10=1,"",IF(C10="","Missing transaction date",IF(NOT(ISNUMBER(C10)),"Invalid date",IF(OR(C10<DATE(2000,1,1),C10>DATE(2099,12,31)),"Invalid date",IF(D10="","Select a type",IF(U10="","Unknown type: "&D10,IF(V10="","Select an account (Category)",IF(ISNA(MATCH(V10,coa_Name,0)),"Unknown account: "&V10,IF(K10="","Select Paid From / Deposited To",IF(ISNA(MATCH(K10,coa_Name,0)),"Unknown account: "&K10,IF(NOT(ISNUMBER(L10)),"Enter an amount",IF(L10=0,"Enter an amount",IF(ABS(W10)>ABS(L10),"Tax is larger than the amount",""))))))))))))) | Y10: =IF(OR(T10=1,X10<>""),"",IF(AND(B10<>"",COUNTIF(tx_ID,B10)>1),"Duplicate transaction ID",IF(AND(L10<0,D10<>"Adjustment"),"Negative amount — check this entry",IF(AND(D10="Customer Payment",G10=""),"Add the customer",IF(AND(D10="Customer Payment",OR(J10="",COUNTIF(ar_No,J10&"")=0)),"Invoice # in Reference not found on AR sheet",IF(AND(D10="Bill Payment",H10=""),"Add the vendor",IF(AND(D10="Bill Payment",OR(J10="",COUNTIFS(ap_No,J10&"",ap_Party,H10&"")=0)),"Bill # + vendor not found on AP sheet",IF(AND(ISNUMBER(M10),N(M10)<>0,W10=0),"Tax ignored (tax tracking off, or not allowed for this type)",IF(V10=K10&"","Same account on both sides",IF(AND(ISNUMBER(StartDate),C10<StartDate),"Date is before the accounting start date",IF(AND(D10<>"Adjustment",IFERROR(INDEX(coa_Pay,MATCH(K10&"",coa_Name,0)),"")<>"Yes"),"Paid From / Deposited To is not a payment account",""))))))))))) | Z10: =IF(AND(T10=0,X10=""),1,0) | AA10: =IF(Z10=1,IF(U10="In",L10,L10-W10),0) | AB10: =IF(Z10=1,IF(U10="In",L10-W10,L10),0) | AC10: =IF(AND(Z10=1,U10="Out"),W10,0) | AD10: =IF(AND(Z10=1,U10="In"),W10,0)
B11: TX-0005 | C11: 46028 | D11: Money Out | E11: Other Direct Costs | F11: Boxes & paper bags (market) | I11: Cash | K11: Cash on Hand | L11: 2776.35 | M11: 297.47 | O11: =IF(Z11=1,L11-W11,"") | P11: =IF(V11="","",IFERROR(INDEX(coa_Type,MATCH(V11,coa_Name,0)),"")) | Q11: =IF(Z11=1,IF(U11="In",K11&"",V11),"") | R11: =IF(Z11=1,IF(U11="In",V11,K11&""),"") | S11: =IF(X11<>"","⛔ "&X11&" — not posted",IF(Y11<>"","⚠ "&Y11,IF(Z11=1,"✓ OK",""))) | T11: =IF(AND(C11="",D11="",E11="",L11="",K11=""),1,0) | U11: =IFERROR(INDEX(tt_Dir,MATCH(D11,tt_Type,0)),"") | V11: =IF(D11="","",IFERROR(IF(INDEX(tt_Other,MATCH(D11,tt_Type,0))="",E11&"",INDEX(tt_Other,MATCH(D11,tt_Type,0))),"")) | W11: =IF(OR(TaxOn<>"Yes",NOT(ISNUMBER(M11))),0,IF(IFERROR(INDEX(tt_Tax,MATCH(D11,tt_Type,0)),"No")="Yes",M11,0)) | X11: =IF(T11=1,"",IF(C11="","Missing transaction date",IF(NOT(ISNUMBER(C11)),"Invalid date",IF(OR(C11<DATE(2000,1,1),C11>DATE(2099,12,31)),"Invalid date",IF(D11="","Select a type",IF(U11="","Unknown type: "&D11,IF(V11="","Select an account (Category)",IF(ISNA(MATCH(V11,coa_Name,0)),"Unknown account: "&V11,IF(K11="","Select Paid From / Deposited To",IF(ISNA(MATCH(K11,coa_Name,0)),"Unknown account: "&K11,IF(NOT(ISNUMBER(L11)),"Enter an amount",IF(L11=0,"Enter an amount",IF(ABS(W11)>ABS(L11),"Tax is larger than the amount",""))))))))))))) | Y11: =IF(OR(T11=1,X11<>""),"",IF(AND(B11<>"",COUNTIF(tx_ID,B11)>1),"Duplicate transaction ID",IF(AND(L11<0,D11<>"Adjustment"),"Negative amount — check this entry",IF(AND(D11="Customer Payment",G11=""),"Add the customer",IF(AND(D11="Customer Payment",OR(J11="",COUNTIF(ar_No,J11&"")=0)),"Invoice # in Reference not found on AR sheet",IF(AND(D11="Bill Payment",H11=""),"Add the vendor",IF(AND(D11="Bill Payment",OR(J11="",COUNTIFS(ap_No,J11&"",ap_Party,H11&"")=0)),"Bill # + vendor not found on AP sheet",IF(AND(ISNUMBER(M11),N(M11)<>0,W11=0),"Tax ignored (tax tracking off, or not allowed for this type)",IF(V11=K11&"","Same account on both sides",IF(AND(ISNUMBER(StartDate),C11<StartDate),"Date is before the accounting start date",IF(AND(D11<>"Adjustment",IFERROR(INDEX(coa_Pay,MATCH(K11&"",coa_Name,0)),"")<>"Yes"),"Paid From / Deposited To is not a payment account",""))))))))))) | Z11: =IF(AND(T11=0,X11=""),1,0) | AA11: =IF(Z11=1,IF(U11="In",L11,L11-W11),0) | AB11: =IF(Z11=1,IF(U11="In",L11-W11,L11),0) | AC11: =IF(AND(Z11=1,U11="Out"),W11,0) | AD11: =IF(AND(Z11=1,U11="In"),W11,0)
B12: TX-0006 | C12: 46030 | D12: Money Out | E12: Advertising & Marketing | F12: Facebook / Instagram ads | I12: Credit Card | K12: Credit Card | L12: 3835.19 | M12: 410.91 | O12: =IF(Z12=1,L12-W12,"") | P12: =IF(V12="","",IFERROR(INDEX(coa_Type,MATCH(V12,coa_Name,0)),"")) | Q12: =IF(Z12=1,IF(U12="In",K12&"",V12),"") | R12: =IF(Z12=1,IF(U12="In",V12,K12&""),"") | S12: =IF(X12<>"","⛔ "&X12&" — not posted",IF(Y12<>"","⚠ "&Y12,IF(Z12=1,"✓ OK",""))) | T12: =IF(AND(C12="",D12="",E12="",L12="",K12=""),1,0) | U12: =IFERROR(INDEX(tt_Dir,MATCH(D12,tt_Type,0)),"") | V12: =IF(D12="","",IFERROR(IF(INDEX(tt_Other,MATCH(D12,tt_Type,0))="",E12&"",INDEX(tt_Other,MATCH(D12,tt_Type,0))),"")) | W12: =IF(OR(TaxOn<>"Yes",NOT(ISNUMBER(M12))),0,IF(IFERROR(INDEX(tt_Tax,MATCH(D12,tt_Type,0)),"No")="Yes",M12,0)) | X12: =IF(T12=1,"",IF(C12="","Missing transaction date",IF(NOT(ISNUMBER(C12)),"Invalid date",IF(OR(C12<DATE(2000,1,1),C12>DATE(2099,12,31)),"Invalid date",IF(D12="","Select a type",IF(U12="","Unknown type: "&D12,IF(V12="","Select an account (Category)",IF(ISNA(MATCH(V12,coa_Name,0)),"Unknown account: "&V12,IF(K12="","Select Paid From / Deposited To",IF(ISNA(MATCH(K12,coa_Name,0)),"Unknown account: "&K12,IF(NOT(ISNUMBER(L12)),"Enter an amount",IF(L12=0,"Enter an amount",IF(ABS(W12)>ABS(L12),"Tax is larger than the amount",""))))))))))))) | Y12: =IF(OR(T12=1,X12<>""),"",IF(AND(B12<>"",COUNTIF(tx_ID,B12)>1),"Duplicate transaction ID",IF(AND(L12<0,D12<>"Adjustment"),"Negative amount — check this entry",IF(AND(D12="Customer Payment",G12=""),"Add the customer",IF(AND(D12="Customer Payment",OR(J12="",COUNTIF(ar_No,J12&"")=0)),"Invoice # in Reference not found on AR sheet",IF(AND(D12="Bill Payment",H12=""),"Add the vendor",IF(AND(D12="Bill Payment",OR(J12="",COUNTIFS(ap_No,J12&"",ap_Party,H12&"")=0)),"Bill # + vendor not found on AP sheet",IF(AND(ISNUMBER(M12),N(M12)<>0,W12=0),"Tax ignored (tax tracking off, or not allowed for this type)",IF(V12=K12&"","Same account on both sides",IF(AND(ISNUMBER(StartDate),C12<StartDate),"Date is before the accounting start date",IF(AND(D12<>"Adjustment",IFERROR(INDEX(coa_Pay,MATCH(K12&"",coa_Name,0)),"")<>"Yes"),"Paid From / Deposited To is not a payment account",""))))))))))) | Z12: =IF(AND(T12=0,X12=""),1,0) | AA12: =IF(Z12=1,IF(U12="In",L12,L12-W12),0) | AB12: =IF(Z12=1,IF(U12="In",L12-W12,L12),0) | AC12: =IF(AND(Z12=1,U12="Out"),W12,0) | AD12: =IF(AND(Z12=1,U12="In"),W12,0)
B13: TX-0007 | C13: 46031 | D13: Money Out | E13: Software & Subscriptions | F13: POS app subscription | I13: Credit Card | K13: Credit Card | L13: 1450 | M13: 155.36 | O13: =IF(Z13=1,L13-W13,"") | P13: =IF(V13="","",IFERROR(INDEX(coa_Type,MATCH(V13,coa_Name,0)),"")) | Q13: =IF(Z13=1,IF(U13="In",K13&"",V13),"") | R13: =IF(Z13=1,IF(U13="In",V13,K13&""),"") | S13: =IF(X13<>"","⛔ "&X13&" — not posted",IF(Y13<>"","⚠ "&Y13,IF(Z13=1,"✓ OK",""))) | T13: =IF(AND(C13="",D13="",E13="",L13="",K13=""),1,0) | U13: =IFERROR(INDEX(tt_Dir,MATCH(D13,tt_Type,0)),"") | V13: =IF(D13="","",IFERROR(IF(INDEX(tt_Other,MATCH(D13,tt_Type,0))="",E13&"",INDEX(tt_Other,MATCH(D13,tt_Type,0))),"")) | W13: =IF(OR(TaxOn<>"Yes",NOT(ISNUMBER(M13))),0,IF(IFERROR(INDEX(tt_Tax,MATCH(D13,tt_Type,0)),"No")="Yes",M13,0)) | X13: =IF(T13=1,"",IF(C13="","Missing transaction date",IF(NOT(ISNUMBER(C13)),"Invalid date",IF(OR(C13<DATE(2000,1,1),C13>DATE(2099,12,31)),"Invalid date",IF(D13="","Select a type",IF(U13="","Unknown type: "&D13,IF(V13="","Select an account (Category)",IF(ISNA(MATCH(V13,coa_Name,0)),"Unknown account: "&V13,IF(K13="","Select Paid From / Deposited To",IF(ISNA(MATCH(K13,coa_Name,0)),"Unknown account: "&K13,IF(NOT(ISNUMBER(L13)),"Enter an amount",IF(L13=0,"Enter an amount",IF(ABS(W13)>ABS(L13),"Tax is larger than the amount",""))))))))))))) | Y13: =IF(OR(T13=1,X13<>""),"",IF(AND(B13<>"",COUNTIF(tx_ID,B13)>1),"Duplicate transaction ID",IF(AND(L13<0,D13<>"Adjustment"),"Negative amount — check this entry",IF(AND(D13="Customer Payment",G13=""),"Add the customer",IF(AND(D13="Customer Payment",OR(J13="",COUNTIF(ar_No,J13&"")=0)),"Invoice # in Reference not found on AR sheet",IF(AND(D13="Bill Payment",H13=""),"Add the vendor",IF(AND(D13="Bill Payment",OR(J13="",COUNTIFS(ap_No,J13&"",ap_Party,H13&"")=0)),"Bill # + vendor not found on AP sheet",IF(AND(ISNUMBER(M13),N(M13)<>0,W13=0),"Tax ignored (tax tracking off, or not allowed for this type)",IF(V13=K13&"","Same account on both sides",IF(AND(ISNUMBER(StartDate),C13<StartDate),"Date is before the accounting start date",IF(AND(D13<>"Adjustment",IFERROR(INDEX(coa_Pay,MATCH(K13&"",coa_Name,0)),"")<>"Yes"),"Paid From / Deposited To is not a payment account",""))))))))))) | Z13: =IF(AND(T13=0,X13=""),1,0) | AA13: =IF(Z13=1,IF(U13="In",L13,L13-W13),0) | AB13: =IF(Z13=1,IF(U13="In",L13-W13,L13),0) | AC13: =IF(AND(Z13=1,U13="Out"),W13,0) | AD13: =IF(AND(Z13=1,U13="In"),W13,0)
B14: TX-0008 | C14: 46032 | D14: Money Out | E14: Loans Payable | F14: Loan principal | I14: Bank Transfer | J14: LOAN | K14: Bank Account | L14: 8000 | O14: =IF(Z14=1,L14-W14,"") | P14: =IF(V14="","",IFERROR(INDEX(coa_Type,MATCH(V14,coa_Name,0)),"")) | Q14: =IF(Z14=1,IF(U14="In",K14&"",V14),"") | R14: =IF(Z14=1,IF(U14="In",V14,K14&""),"") | S14: =IF(X14<>"","⛔ "&X14&" — not posted",IF(Y14<>"","⚠ "&Y14,IF(Z14=1,"✓ OK",""))) | T14: =IF(AND(C14="",D14="",E14="",L14="",K14=""),1,0) | U14: =IFERROR(INDEX(tt_Dir,MATCH(D14,tt_Type,0)),"") | V14: =IF(D14="","",IFERROR(IF(INDEX(tt_Other,MATCH(D14,tt_Type,0))="",E14&"",INDEX(tt_Other,MATCH(D14,tt_Type,0))),"")) | W14: =IF(OR(TaxOn<>"Yes",NOT(ISNUMBER(M14))),0,IF(IFERROR(INDEX(tt_Tax,MATCH(D14,tt_Type,0)),"No")="Yes",M14,0)) | X14: =IF(T14=1,"",IF(C14="","Missing transaction date",IF(NOT(ISNUMBER(C14)),"Invalid date",IF(OR(C14<DATE(2000,1,1),C14>DATE(2099,12,31)),"Invalid date",IF(D14="","Select a type",IF(U14="","Unknown type: "&D14,IF(V14="","Select an account (Category)",IF(ISNA(MATCH(V14,coa_Name,0)),"Unknown account: "&V14,IF(K14="","Select Paid From / Deposited To",IF(ISNA(MATCH(K14,coa_Name,0)),"Unknown account: "&K14,IF(NOT(ISNUMBER(L14)),"Enter an amount",IF(L14=0,"Enter an amount",IF(ABS(W14)>ABS(L14),"Tax is larger than the amount",""))))))))))))) | Y14: =IF(OR(T14=1,X14<>""),"",IF(AND(B14<>"",COUNTIF(tx_ID,B14)>1),"Duplicate transaction ID",IF(AND(L14<0,D14<>"Adjustment"),"Negative amount — check this entry",IF(AND(D14="Customer Payment",G14=""),"Add the customer",IF(AND(D14="Customer Payment",OR(J14="",COUNTIF(ar_No,J14&"")=0)),"Invoice # in Reference not found on AR sheet",IF(AND(D14="Bill Payment",H14=""),"Add the vendor",IF(AND(D14="Bill Payment",OR(J14="",COUNTIFS(ap_No,J14&"",ap_Party,H14&"")=0)),"Bill # + vendor not found on AP sheet",IF(AND(ISNUMBER(M14),N(M14)<>0,W14=0),"Tax ignored (tax tracking off, or not allowed for this type)",IF(V14=K14&"","Same account on both sides",IF(AND(ISNUMBER(StartDate),C14<StartDate),"Date is before the accounting start date",IF(AND(D14<>"Adjustment",IFERROR(INDEX(coa_Pay,MATCH(K14&"",coa_Name,0)),"")<>"Yes"),"Paid From / Deposited To is not a payment account",""))))))))))) | Z14: =IF(AND(T14=0,X14=""),1,0) | AA14: =IF(Z14=1,IF(U14="In",L14,L14-W14),0) | AB14: =IF(Z14=1,IF(U14="In",L14-W14,L14),0) | AC14: =IF(AND(Z14=1,U14="Out"),W14,0) | AD14: =IF(AND(Z14=1,U14="In"),W14,0)
B15: TX-0009 | C15: 46032 | D15: Money Out | E15: Interest Expense | F15: Loan interest | I15: Bank Transfer | J15: LOAN | K15: Bank Account | L15: 1500 | O15: =IF(Z15=1,L15-W15,"") | P15: =IF(V15="","",IFERROR(INDEX(coa_Type,MATCH(V15,coa_Name,0)),"")) | Q15: =IF(Z15=1,IF(U15="In",K15&"",V15),"") | R15: =IF(Z15=1,IF(U15="In",V15,K15&""),"") | S15: =IF(X15<>"","⛔ "&X15&" — not posted",IF(Y15<>"","⚠ "&Y15,IF(Z15=1,"✓ OK",""))) | T15: =IF(AND(C15="",D15="",E15="",L15="",K15=""),1,0) | U15: =IFERROR(INDEX(tt_Dir,MATCH(D15,tt_Type,0)),"") | V15: =IF(D15="","",IFERROR(IF(INDEX(tt_Other,MATCH(D15,tt_Type,0))="",E15&"",INDEX(tt_Other,MATCH(D15,tt_Type,0))),"")) | W15: =IF(OR(TaxOn<>"Yes",NOT(ISNUMBER(M15))),0,IF(IFERROR(INDEX(tt_Tax,MATCH(D15,tt_Type,0)),"No")="Yes",M15,0)) | X15: =IF(T15=1,"",IF(C15="","Missing transaction date",IF(NOT(ISNUMBER(C15)),"Invalid date",IF(OR(C15<DATE(2000,1,1),C15>DATE(2099,12,31)),"Invalid date",IF(D15="","Select a type",IF(U15="","Unknown type: "&D15,IF(V15="","Select an account (Category)",IF(ISNA(MATCH(V15,coa_Name,0)),"Unknown account: "&V15,IF(K15="","Select Paid From / Deposited To",IF(ISNA(MATCH(K15,coa_Name,0)),"Unknown account: "&K15,IF(NOT(ISNUMBER(L15)),"Enter an amount",IF(L15=0,"Enter an amount",IF(ABS(W15)>ABS(L15),"Tax is larger than the amount",""))))))))))))) | Y15: =IF(OR(T15=1,X15<>""),"",IF(AND(B15<>"",COUNTIF(tx_ID,B15)>1),"Duplicate transaction ID",IF(AND(L15<0,D15<>"Adjustment"),"Negative amount — check this entry",IF(AND(D15="Customer Payment",G15=""),"Add the customer",IF(AND(D15="Customer Payment",OR(J15="",COUNTIF(ar_No,J15&"")=0)),"Invoice # in Reference not found on AR sheet",IF(AND(D15="Bill Payment",H15=""),"Add the vendor",IF(AND(D15="Bill Payment",OR(J15="",COUNTIFS(ap_No,J15&"",ap_Party,H15&"")=0)),"Bill # + vendor not found on AP sheet",IF(AND(ISNUMBER(M15),N(M15)<>0,W15=0),"Tax ignored (tax tracking off, or not allowed for this type)",IF(V15=K15&"","Same account on both sides",IF(AND(ISNUMBER(StartDate),C15<StartDate),"Date is before the accounting start date",IF(AND(D15<>"Adjustment",IFERROR(INDEX(coa_Pay,MATCH(K15&"",coa_Name,0)),"")<>"Yes"),"Paid From / Deposited To is not a payment account",""))))))))))) | Z15: =IF(AND(T15=0,X15=""),1,0) | AA15: =IF(Z15=1,IF(U15="In",L15,L15-W15),0) | AB15: =IF(Z15=1,IF(U15="In",L15-W15,L15),0) | AC15: =IF(AND(Z15=1,U15="Out"),W15,0) | AD15: =IF(AND(Z15=1,U15="In"),W15,0)
B16: TX-0010 | C16: 46033 | D16: Money In | E16: Product Sales | F16: Counter sales week 2 | I16: Cash | K16: Cash on Hand | L16: 42316.87 | M16: 4533.95 | O16: =IF(Z16=1,L16-W16,"") | P16: =IF(V16="","",IFERROR(INDEX(coa_Type,MATCH(V16,coa_Name,0)),"")) | Q16: =IF(Z16=1,IF(U16="In",K16&"",V16),"") | R16: =IF(Z16=1,IF(U16="In",V16,K16&""),"") | S16: =IF(X16<>"","⛔ "&X16&" — not posted",IF(Y16<>"","⚠ "&Y16,IF(Z16=1,"✓ OK",""))) | T16: =IF(AND(C16="",D16="",E16="",L16="",K16=""),1,0) | U16: =IFERROR(INDEX(tt_Dir,MATCH(D16,tt_Type,0)),"") | V16: =IF(D16="","",IFERROR(IF(INDEX(tt_Other,MATCH(D16,tt_Type,0))="",E16&"",INDEX(tt_Other,MATCH(D16,tt_Type,0))),"")) | W16: =IF(OR(TaxOn<>"Yes",NOT(ISNUMBER(M16))),0,IF(IFERROR(INDEX(tt_Tax,MATCH(D16,tt_Type,0)),"No")="Yes",M16,0)) | X16: =IF(T16=1,"",IF(C16="","Missing transaction date",IF(NOT(ISNUMBER(C16)),"Invalid date",IF(OR(C16<DATE(2000,1,1),C16>DATE(2099,12,31)),"Invalid date",IF(D16="","Select a type",IF(U16="","Unknown type: "&D16,IF(V16="","Select an account (Category)",IF(ISNA(MATCH(V16,coa_Name,0)),"Unknown account: "&V16,IF(K16="","Select Paid From / Deposited To",IF(ISNA(MATCH(K16,coa_Name,0)),"Unknown account: "&K16,IF(NOT(ISNUMBER(L16)),"Enter an amount",IF(L16=0,"Enter an amount",IF(ABS(W16)>ABS(L16),"Tax is larger than the amount",""))))))))))))) | Y16: =IF(OR(T16=1,X16<>""),"",IF(AND(B16<>"",COUNTIF(tx_ID,B16)>1),"Duplicate transaction ID",IF(AND(L16<0,D16<>"Adjustment"),"Negative amount — check this entry",IF(AND(D16="Customer Payment",G16=""),"Add the customer",IF(AND(D16="Customer Payment",OR(J16="",COUNTIF(ar_No,J16&"")=0)),"Invoice # in Reference not found on AR sheet",IF(AND(D16="Bill Payment",H16=""),"Add the vendor",IF(AND(D16="Bill Payment",OR(J16="",COUNTIFS(ap_No,J16&"",ap_Party,H16&"")=0)),"Bill # + vendor not found on AP sheet",IF(AND(ISNUMBER(M16),N(M16)<>0,W16=0),"Tax ignored (tax tracking off, or not allowed for this type)",IF(V16=K16&"","Same account on both sides",IF(AND(ISNUMBER(StartDate),C16<StartDate),"Date is before the accounting start date",IF(AND(D16<>"Adjustment",IFERROR(INDEX(coa_Pay,MATCH(K16&"",coa_Name,0)),"")<>"Yes"),"Paid From / Deposited To is not a payment account",""))))))))))) | Z16: =IF(AND(T16=0,X16=""),1,0) | AA16: =IF(Z16=1,IF(U16="In",L16,L16-W16),0) | AB16: =IF(Z16=1,IF(U16="In",L16-W16,L16),0) | AC16: =IF(AND(Z16=1,U16="Out"),W16,0) | AD16: =IF(AND(Z16=1,U16="In"),W16,0)
B17: TX-0011 | C17: 46034 | D17: Money In | E17: Product Sales | F17: GCash / online orders week 2 | I17: E-Wallet | K17: E-Wallet / Online Payments | L17: 22825.17 | M17: 2445.55 | O17: =IF(Z17=1,L17-W17,"") | P17: =IF(V17="","",IFERROR(INDEX(coa_Type,MATCH(V17,coa_Name,0)),"")) | Q17: =IF(Z17=1,IF(U17="In",K17&"",V17),"") | R17: =IF(Z17=1,IF(U17="In",V17,K17&""),"") | S17: =IF(X17<>"","⛔ "&X17&" — not posted",IF(Y17<>"","⚠ "&Y17,IF(Z17=1,"✓ OK",""))) | T17: =IF(AND(C17="",D17="",E17="",L17="",K17=""),1,0) | U17: =IFERROR(INDEX(tt_Dir,MATCH(D17,tt_Type,0)),"") | V17: =IF(D17="","",IFERROR(IF(INDEX(tt_Other,MATCH(D17,tt_Type,0))="",E17&"",INDEX(tt_Other,MATCH(D17,tt_Type,0))),"")) | W17: =IF(OR(TaxOn<>"Yes",NOT(ISNUMBER(M17))),0,IF(IFERROR(INDEX(tt_Tax,MATCH(D17,tt_Type,0)),"No")="Yes",M17,0)) | X17: =IF(T17=1,"",IF(C17="","Missing transaction date",IF(NOT(ISNUMBER(C17)),"Invalid date",IF(OR(C17<DATE(2000,1,1),C17>DATE(2099,12,31)),"Invalid date",IF(D17="","Select a type",IF(U17="","Unknown type: "&D17,IF(V17="","Select an account (Category)",IF(ISNA(MATCH(V17,coa_Name,0)),"Unknown account: "&V17,IF(K17="","Select Paid From / Deposited To",IF(ISNA(MATCH(K17,coa_Name,0)),"Unknown account: "&K17,IF(NOT(ISNUMBER(L17)),"Enter an amount",IF(L17=0,"Enter an amount",IF(ABS(W17)>ABS(L17),"Tax is larger than the amount",""))))))))))))) | Y17: =IF(OR(T17=1,X17<>""),"",IF(AND(B17<>"",COUNTIF(tx_ID,B17)>1),"Duplicate transaction ID",IF(AND(L17<0,D17<>"Adjustment"),"Negative amount — check this entry",IF(AND(D17="Customer Payment",G17=""),"Add the customer",IF(AND(D17="Customer Payment",OR(J17="",COUNTIF(ar_No,J17&"")=0)),"Invoice # in Reference not found on AR sheet",IF(AND(D17="Bill Payment",H17=""),"Add the vendor",IF(AND(D17="Bill Payment",OR(J17="",COUNTIFS(ap_No,J17&"",ap_Party,H17&"")=0)),"Bill # + vendor not found on AP sheet",IF(AND(ISNUMBER(M17),N(M17)<>0,W17=0),"Tax ignored (tax tracking off, or not allowed for this type)",IF(V17=K17&"","Same account on both sides",IF(AND(ISNUMBER(StartDate),C17<StartDate),"Date is before the accounting start date",IF(AND(D17<>"Adjustment",IFERROR(INDEX(coa_Pay,MATCH(K17&"",coa_Name,0)),"")<>"Yes"),"Paid From / Deposited To is not a payment account",""))))))))))) | Z17: =IF(AND(T17=0,X17=""),1,0) | AA17: =IF(Z17=1,IF(U17="In",L17,L17-W17),0) | AB17: =IF(Z17=1,IF(U17="In",L17-W17,L17),0) | AC17: =IF(AND(Z17=1,U17="Out"),W17,0) | AD17: =IF(AND(Z17=1,U17="In"),W17,0)
B18: TX-0012 | C18: 46034 | D18: Money Out | E18: Utilities | F18: Electricity & water | I18: Bank Transfer | K18: Bank Account | L18: 9162.96 | M18: 981.75 | O18: =IF(Z18=1,L18-W18,"") | P18: =IF(V18="","",IFERROR(INDEX(coa_Type,MATCH(V18,coa_Name,0)),"")) | Q18: =IF(Z18=1,IF(U18="In",K18&"",V18),"") | R18: =IF(Z18=1,IF(U18="In",V18,K18&""),"") | S18: =IF(X18<>"","⛔ "&X18&" — not posted",IF(Y18<>"","⚠ "&Y18,IF(Z18=1,"✓ OK",""))) | T18: =IF(AND(C18="",D18="",E18="",L18="",K18=""),1,0) | U18: =IFERROR(INDEX(tt_Dir,MATCH(D18,tt_Type,0)),"") | V18: =IF(D18="","",IFERROR(IF(INDEX(tt_Other,MATCH(D18,tt_Type,0))="",E18&"",INDEX(tt_Other,MATCH(D18,tt_Type,0))),"")) | W18: =IF(OR(TaxOn<>"Yes",NOT(ISNUMBER(M18))),0,IF(IFERROR(INDEX(tt_Tax,MATCH(D18,tt_Type,0)),"No")="Yes",M18,0)) | X18: =IF(T18=1,"",IF(C18="","Missing transaction date",IF(NOT(ISNUMBER(C18)),"Invalid date",IF(OR(C18<DATE(2000,1,1),C18>DATE(2099,12,31)),"Invalid date",IF(D18="","Select a type",IF(U18="","Unknown type: "&D18,IF(V18="","Select an account (Category)",IF(ISNA(MATCH(V18,coa_Name,0)),"Unknown account: "&V18,IF(K18="","Select Paid From / Deposited To",IF(ISNA(MATCH(K18,coa_Name,0)),"Unknown account: "&K18,IF(NOT(ISNUMBER(L18)),"Enter an amount",IF(L18=0,"Enter an amount",IF(ABS(W18)>ABS(L18),"Tax is larger than the amount",""))))))))))))) | Y18: =IF(OR(T18=1,X18<>""),"",IF(AND(B18<>"",COUNTIF(tx_ID,B18)>1),"Duplicate transaction ID",IF(AND(L18<0,D18<>"Adjustment"),"Negative amount — check this entry",IF(AND(D18="Customer Payment",G18=""),"Add the customer",IF(AND(D18="Customer Payment",OR(J18="",COUNTIF(ar_No,J18&"")=0)),"Invoice # in Reference not found on AR sheet",IF(AND(D18="Bill Payment",H18=""),"Add the vendor",IF(AND(D18="Bill Payment",OR(J18="",COUNTIFS(ap_No,J18&"",ap_Party,H18&"")=0)),"Bill # + vendor not found on AP sheet",IF(AND(ISNUMBER(M18),N(M18)<>0,W18=0),"Tax ignored (tax tracking off, or not allowed for this type)",IF(V18=K18&"","Same account on both sides",IF(AND(ISNUMBER(StartDate),C18<StartDate),"Date is before the accounting start date",IF(AND(D18<>"Adjustment",IFERROR(INDEX(coa_Pay,MATCH(K18&"",coa_Name,0)),"")<>"Yes"),"Paid From / Deposited To is not a payment account",""))))))))))) | Z18: =IF(AND(T18=0,X18=""),1,0) | AA18: =IF(Z18=1,IF(U18="In",L18,L18-W18),0) | AB18: =IF(Z18=1,IF(U18="In",L18-W18,L18),0) | AC18: =IF(AND(Z18=1,U18="Out"),W18,0) | AD18: =IF(AND(Z18=1,U18="In"),W18,0)
B19: TX-0013 | C19: 46035 | D19: Transfer | E19: Bank Account | F19: Cash deposit to bank | I19: Cash | K19: Cash on Hand | L19: 36000 | O19: =IF(Z19=1,L19-W19,"") | P19: =IF(V19="","",IFERROR(INDEX(coa_Type,MATCH(V19,coa_Name,0)),"")) | Q19: =IF(Z19=1,IF(U19="In",K19&"",V19),"") | R19: =IF(Z19=1,IF(U19="In",V19,K19&""),"") | S19: =IF(X19<>"","⛔ "&X19&" — not posted",IF(Y19<>"","⚠ "&Y19,IF(Z19=1,"✓ OK",""))) | T19: =IF(AND(C19="",D19="",E19="",L19="",K19=""),1,0) | U19: =IFERROR(INDEX(tt_Dir,MATCH(D19,tt_Type,0)),"") | V19: =IF(D19="","",IFERROR(IF(INDEX(tt_Other,MATCH(D19,tt_Type,0))="",E19&"",INDEX(tt_Other,MATCH(D19,tt_Type,0))),"")) | W19: =IF(OR(TaxOn<>"Yes",NOT(ISNUMBER(M19))),0,IF(IFERROR(INDEX(tt_Tax,MATCH(D19,tt_Type,0)),"No")="Yes",M19,0)) | X19: =IF(T19=1,"",IF(C19="","Missing transaction date",IF(NOT(ISNUMBER(C19)),"Invalid date",IF(OR(C19<DATE(2000,1,1),C19>DATE(2099,12,31)),"Invalid date",IF(D19="","Select a type",IF(U19="","Unknown type: "&D19,IF(V19="","Select an account (Category)",IF(ISNA(MATCH(V19,coa_Name,0)),"Unknown account: "&V19,IF(K19="","Select Paid From / Deposited To",IF(ISNA(MATCH(K19,coa_Name,0)),"Unknown account: "&K19,IF(NOT(ISNUMBER(L19)),"Enter an amount",IF(L19=0,"Enter an amount",IF(ABS(W19)>ABS(L19),"Tax is larger than the amount",""))))))))))))) | Y19: =IF(OR(T19=1,X19<>""),"",IF(AND(B19<>"",COUNTIF(tx_ID,B19)>1),"Duplicate transaction ID",IF(AND(L19<0,D19<>"Adjustment"),"Negative amount — check this entry",IF(AND(D19="Customer Payment",G19=""),"Add the customer",IF(AND(D19="Customer Payment",OR(J19="",COUNTIF(ar_No,J19&"")=0)),"Invoice # in Reference not found on AR sheet",IF(AND(D19="Bill Payment",H19=""),"Add the vendor",IF(AND(D19="Bill Payment",OR(J19="",COUNTIFS(ap_No,J19&"",ap_Party,H19&"")=0)),"Bill # + vendor not found on AP sheet",IF(AND(ISNUMBER(M19),N(M19)<>0,W19=0),"Tax ignored (tax tracking off, or not allowed for this type)",IF(V19=K19&"","Same account on both sides",IF(AND(ISNUMBER(StartDate),C19<StartDate),"Date is before the accounting start date",IF(AND(D19<>"Adjustment",IFERROR(INDEX(coa_Pay,MATCH(K19&"",coa_Name,0)),"")<>"Yes"),"Paid From / Deposited To is not a payment account",""))))))))))) | Z19: =IF(AND(T19=0,X19=""),1,0) | AA19: =IF(Z19=1,IF(U19="In",L19,L19-W19),0) | AB19: =IF(Z19=1,IF(U19="In",L19-W19,L19),0) | AC19: =IF(AND(Z19=1,U19="Out"),W19,0) | AD19: =IF(AND(Z19=1,U19="In"),W19,0)
B20: TX-0014 | C20: 46037 | D20: Money Out | E20: Internet & Phone | F20: Fiber internet | I20: Bank Transfer | K20: Bank Account | L20: 2499 | M20: 267.75 | O20: =IF(Z20=1,L20-W20,"") | P20: =IF(V20="","",IFERROR(INDEX(coa_Type,MATCH(V20,coa_Name,0)),"")) | Q20: =IF(Z20=1,IF(U20="In",K20&"",V20),"") | R20: =IF(Z20=1,IF(U20="In",V20,K20&""),"") | S20: =IF(X20<>"","⛔ "&X20&" — not posted",IF(Y20<>"","⚠ "&Y20,IF(Z20=1,"✓ OK",""))) | T20: =IF(AND(C20="",D20="",E20="",L20="",K20=""),1,0) | U20: =IFERROR(INDEX(tt_Dir,MATCH(D20,tt_Type,0)),"") | V20: =IF(D20="","",IFERROR(IF(INDEX(tt_Other,MATCH(D20,tt_Type,0))="",E20&"",INDEX(tt_Other,MATCH(D20,tt_Type,0))),"")) | W20: =IF(OR(TaxOn<>"Yes",NOT(ISNUMBER(M20))),0,IF(IFERROR(INDEX(tt_Tax,MATCH(D20,tt_Type,0)),"No")="Yes",M20,0)) | X20: =IF(T20=1,"",IF(C20="","Missing transaction date",IF(NOT(ISNUMBER(C20)),"Invalid date",IF(OR(C20<DATE(2000,1,1),C20>DATE(2099,12,31)),"Invalid date",IF(D20="","Select a type",IF(U20="","Unknown type: "&D20,IF(V20="","Select an account (Category)",IF(ISNA(MATCH(V20,coa_Name,0)),"Unknown account: "&V20,IF(K20="","Select Paid From / Deposited To",IF(ISNA(MATCH(K20,coa_Name,0)),"Unknown account: "&K20,IF(NOT(ISNUMBER(L20)),"Enter an amount",IF(L20=0,"Enter an amount",IF(ABS(W20)>ABS(L20),"Tax is larger than the amount",""))))))))))))) | Y20: =IF(OR(T20=1,X20<>""),"",IF(AND(B20<>"",COUNTIF(tx_ID,B20)>1),"Duplicate transaction ID",IF(AND(L20<0,D20<>"Adjustment"),"Negative amount — check this entry",IF(AND(D20="Customer Payment",G20=""),"Add the customer",IF(AND(D20="Customer Payment",OR(J20="",COUNTIF(ar_No,J20&"")=0)),"Invoice # in Reference not found on AR sheet",IF(AND(D20="Bill Payment",H20=""),"Add the vendor",IF(AND(D20="Bill Payment",OR(J20="",COUNTIFS(ap_No,J20&"",ap_Party,H20&"")=0)),"Bill # + vendor not found on AP sheet",IF(AND(ISNUMBER(M20),N(M20)<>0,W20=0),"Tax ignored (tax tracking off, or not allowed for this type)",IF(V20=K20&"","Same account on both sides",IF(AND(ISNUMBER(StartDate),C20<StartDate),"Date is before the accounting start date",IF(AND(D20<>"Adjustment",IFERROR(INDEX(coa_Pay,MATCH(K20&"",coa_Name,0)),"")<>"Yes"),"Paid From / Deposited To is not a payment account",""))))))))))) | Z20: =IF(AND(T20=0,X20=""),1,0) | AA20: =IF(Z20=1,IF(U20="In",L20,L20-W20),0) | AB20: =IF(Z20=1,IF(U20="In",L20-W20,L20),0) | AC20: =IF(AND(Z20=1,U20="Out"),W20,0) | AD20: =IF(AND(Z20=1,U20="In"),W20,0)
B21: TX-0015 | C21: 46037 | D21: Money Out | E21: Direct Labor | F21: Bakers' salaries (1st-15th) | I21: Bank Transfer | K21: Bank Account | L21: 38000 | O21: =IF(Z21=1,L21-W21,"") | P21: =IF(V21="","",IFERROR(INDEX(coa_Type,MATCH(V21,coa_Name,0)),"")) | Q21: =IF(Z21=1,IF(U21="In",K21&"",V21),"") | R21: =IF(Z21=1,IF(U21="In",V21,K21&""),"") | S21: =IF(X21<>"","⛔ "&X21&" — not posted",IF(Y21<>"","⚠ "&Y21,IF(Z21=1,"✓ OK",""))) | T21: =IF(AND(C21="",D21="",E21="",L21="",K21=""),1,0) | U21: =IFERROR(INDEX(tt_Dir,MATCH(D21,tt_Type,0)),"") | V21: =IF(D21="","",IFERROR(IF(INDEX(tt_Other,MATCH(D21,tt_Type,0))="",E21&"",INDEX(tt_Other,MATCH(D21,tt_Type,0))),"")) | W21: =IF(OR(TaxOn<>"Yes",NOT(ISNUMBER(M21))),0,IF(IFERROR(INDEX(tt_Tax,MATCH(D21,tt_Type,0)),"No")="Yes",M21,0)) | X21: =IF(T21=1,"",IF(C21="","Missing transaction date",IF(NOT(ISNUMBER(C21)),"Invalid date",IF(OR(C21<DATE(2000,1,1),C21>DATE(2099,12,31)),"Invalid date",IF(D21="","Select a type",IF(U21="","Unknown type: "&D21,IF(V21="","Select an account (Category)",IF(ISNA(MATCH(V21,coa_Name,0)),"Unknown account: "&V21,IF(K21="","Select Paid From / Deposited To",IF(ISNA(MATCH(K21,coa_Name,0)),"Unknown account: "&K21,IF(NOT(ISNUMBER(L21)),"Enter an amount",IF(L21=0,"Enter an amount",IF(ABS(W21)>ABS(L21),"Tax is larger than the amount",""))))))))))))) | Y21: =IF(OR(T21=1,X21<>""),"",IF(AND(B21<>"",COUNTIF(tx_ID,B21)>1),"Duplicate transaction ID",IF(AND(L21<0,D21<>"Adjustment"),"Negative amount — check this entry",IF(AND(D21="Customer Payment",G21=""),"Add the customer",IF(AND(D21="Customer Payment",OR(J21="",COUNTIF(ar_No,J21&"")=0)),"Invoice # in Reference not found on AR sheet",IF(AND(D21="Bill Payment",H21=""),"Add the vendor",IF(AND(D21="Bill Payment",OR(J21="",COUNTIFS(ap_No,J21&"",ap_Party,H21&"")=0)),"Bill # + vendor not found on AP sheet",IF(AND(ISNUMBER(M21),N(M21)<>0,W21=0),"Tax ignored (tax tracking off, or not allowed for this type)",IF(V21=K21&"","Same account on both sides",IF(AND(ISNUMBER(StartDate),C21<StartDate),"Date is before the accounting start date",IF(AND(D21<>"Adjustment",IFERROR(INDEX(coa_Pay,MATCH(K21&"",coa_Name,0)),"")<>"Yes"),"Paid From / Deposited To is not a payment account",""))))))))))) | Z21: =IF(AND(T21=0,X21=""),1,0) | AA21: =IF(Z21=1,IF(U21="In",L21,L21-W21),0) | AB21: =IF(Z21=1,IF(U21="In",L21-W21,L21),0) | AC21: =IF(AND(Z21=1,U21="Out"),W21,0) | AD21: =IF(AND(Z21=1,U21="In"),W21,0)
B22: TX-0016 | C22: 46037 | D22: Money Out | E22: Salaries & Wages | F22: Cashier salary (1st-15th) | I22: Bank Transfer | K22: Bank Account | L22: 9000 | O22: =IF(Z22=1,L22-W22,"") | P22: =IF(V22="","",IFERROR(INDEX(coa_Type,MATCH(V22,coa_Name,0)),"")) | Q22: =IF(Z22=1,IF(U22="In",K22&"",V22),"") | R22: =IF(Z22=1,IF(U22="In",V22,K22&""),"") | S22: =IF(X22<>"","⛔ "&X22&" — not posted",IF(Y22<>"","⚠ "&Y22,IF(Z22=1,"✓ OK",""))) | T22: =IF(AND(C22="",D22="",E22="",L22="",K22=""),1,0) | U22: =IFERROR(INDEX(tt_Dir,MATCH(D22,tt_Type,0)),"") | V22: =IF(D22="","",IFERROR(IF(INDEX(tt_Other,MATCH(D22,tt_Type,0))="",E22&"",INDEX(tt_Other,MATCH(D22,tt_Type,0))),"")) | W22: =IF(OR(TaxOn<>"Yes",NOT(ISNUMBER(M22))),0,IF(IFERROR(INDEX(tt_Tax,MATCH(D22,tt_Type,0)),"No")="Yes",M22,0)) | X22: =IF(T22=1,"",IF(C22="","Missing transaction date",IF(NOT(ISNUMBER(C22)),"Invalid date",IF(OR(C22<DATE(2000,1,1),C22>DATE(2099,12,31)),"Invalid date",IF(D22="","Select a type",IF(U22="","Unknown type: "&D22,IF(V22="","Select an account (Category)",IF(ISNA(MATCH(V22,coa_Name,0)),"Unknown account: "&V22,IF(K22="","Select Paid From / Deposited To",IF(ISNA(MATCH(K22,coa_Name,0)),"Unknown account: "&K22,IF(NOT(ISNUMBER(L22)),"Enter an amount",IF(L22=0,"Enter an amount",IF(ABS(W22)>ABS(L22),"Tax is larger than the amount",""))))))))))))) | Y22: =IF(OR(T22=1,X22<>""),"",IF(AND(B22<>"",COUNTIF(tx_ID,B22)>1),"Duplicate transaction ID",IF(AND(L22<0,D22<>"Adjustment"),"Negative amount — check this entry",IF(AND(D22="Customer Payment",G22=""),"Add the customer",IF(AND(D22="Customer Payment",OR(J22="",COUNTIF(ar_No,J22&"")=0)),"Invoice # in Reference not found on AR sheet",IF(AND(D22="Bill Payment",H22=""),"Add the vendor",IF(AND(D22="Bill Payment",OR(J22="",COUNTIFS(ap_No,J22&"",ap_Party,H22&"")=0)),"Bill # + vendor not found on AP sheet",IF(AND(ISNUMBER(M22),N(M22)<>0,W22=0),"Tax ignored (tax tracking off, or not allowed for this type)",IF(V22=K22&"","Same account on both sides",IF(AND(ISNUMBER(StartDate),C22<StartDate),"Date is before the accounting start date",IF(AND(D22<>"Adjustment",IFERROR(INDEX(coa_Pay,MATCH(K22&"",coa_Name,0)),"")<>"Yes"),"Paid From / Deposited To is not a payment account",""))))))))))) | Z22: =IF(AND(T22=0,X22=""),1,0) | AA22: =IF(Z22=1,IF(U22="In",L22,L22-W22),0) | AB22: =IF(Z22=1,IF(U22="In",L22-W22,L22),0) | AC22: =IF(AND(Z22=1,U22="Out"),W22,0) | AD22: =IF(AND(Z22=1,U22="In"),W22,0)
B23: TX-0017 | C23: 46040 | D23: Money In | E23: Product Sales | F23: Counter sales week 3 | I23: Cash | K23: Cash on Hand | L23: 61115.56 | M23: 6548.1 | O23: =IF(Z23=1,L23-W23,"") | P23: =IF(V23="","",IFERROR(INDEX(coa_Type,MATCH(V23,coa_Name,0)),"")) | Q23: =IF(Z23=1,IF(U23="In",K23&"",V23),"") | R23: =IF(Z23=1,IF(U23="In",V23,K23&""),"") | S23: =IF(X23<>"","⛔ "&X23&" — not posted",IF(Y23<>"","⚠ "&Y23,IF(Z23=1,"✓ OK",""))) | T23: =IF(AND(C23="",D23="",E23="",L23="",K23=""),1,0) | U23: =IFERROR(INDEX(tt_Dir,MATCH(D23,tt_Type,0)),"") | V23: =IF(D23="","",IFERROR(IF(INDEX(tt_Other,MATCH(D23,tt_Type,0))="",E23&"",INDEX(tt_Other,MATCH(D23,tt_Type,0))),"")) | W23: =IF(OR(TaxOn<>"Yes",NOT(ISNUMBER(M23))),0,IF(IFERROR(INDEX(tt_Tax,MATCH(D23,tt_Type,0)),"No")="Yes",M23,0)) | X23: =IF(T23=1,"",IF(C23="","Missing transaction date",IF(NOT(ISNUMBER(C23)),"Invalid date",IF(OR(C23<DATE(2000,1,1),C23>DATE(2099,12,31)),"Invalid date",IF(D23="","Select a type",IF(U23="","Unknown type: "&D23,IF(V23="","Select an account (Category)",IF(ISNA(MATCH(V23,coa_Name,0)),"Unknown account: "&V23,IF(K23="","Select Paid From / Deposited To",IF(ISNA(MATCH(K23,coa_Name,0)),"Unknown account: "&K23,IF(NOT(ISNUMBER(L23)),"Enter an amount",IF(L23=0,"Enter an amount",IF(ABS(W23)>ABS(L23),"Tax is larger than the amount",""))))))))))))) | Y23: =IF(OR(T23=1,X23<>""),"",IF(AND(B23<>"",COUNTIF(tx_ID,B23)>1),"Duplicate transaction ID",IF(AND(L23<0,D23<>"Adjustment"),"Negative amount — check this entry",IF(AND(D23="Customer Payment",G23=""),"Add the customer",IF(AND(D23="Customer Payment",OR(J23="",COUNTIF(ar_No,J23&"")=0)),"Invoice # in Reference not found on AR sheet",IF(AND(D23="Bill Payment",H23=""),"Add the vendor",IF(AND(D23="Bill Payment",OR(J23="",COUNTIFS(ap_No,J23&"",ap_Party,H23&"")=0)),"Bill # + vendor not found on AP sheet",IF(AND(ISNUMBER(M23),N(M23)<>0,W23=0),"Tax ignored (tax tracking off, or not allowed for this type)",IF(V23=K23&"","Same account on both sides",IF(AND(ISNUMBER(StartDate),C23<StartDate),"Date is before the accounting start date",IF(AND(D23<>"Adjustment",IFERROR(INDEX(coa_Pay,MATCH(K23&"",coa_Name,0)),"")<>"Yes"),"Paid From / Deposited To is not a payment account",""))))))))))) | Z23: =IF(AND(T23=0,X23=""),1,0) | AA23: =IF(Z23=1,IF(U23="In",L23,L23-W23),0) | AB23: =IF(Z23=1,IF(U23="In",L23-W23,L23),0) | AC23: =IF(AND(Z23=1,U23="Out"),W23,0) | AD23: =IF(AND(Z23=1,U23="In"),W23,0)
B24: TX-0018 | C24: 46041 | D24: Money In | E24: Product Sales | F24: GCash / online orders week 3 | I24: E-Wallet | K24: E-Wallet / Online Payments | L24: 17837.56 | M24: 1911.17 | O24: =IF(Z24=1,L24-W24,"") | P24: =IF(V24="","",IFERROR(INDEX(coa_Type,MATCH(V24,coa_Name,0)),"")) | Q24: =IF(Z24=1,IF(U24="In",K24&"",V24),"") | R24: =IF(Z24=1,IF(U24="In",V24,K24&""),"") | S24: =IF(X24<>"","⛔ "&X24&" — not posted",IF(Y24<>"","⚠ "&Y24,IF(Z24=1,"✓ OK",""))) | T24: =IF(AND(C24="",D24="",E24="",L24="",K24=""),1,0) | U24: =IFERROR(INDEX(tt_Dir,MATCH(D24,tt_Type,0)),"") | V24: =IF(D24="","",IFERROR(IF(INDEX(tt_Other,MATCH(D24,tt_Type,0))="",E24&"",INDEX(tt_Other,MATCH(D24,tt_Type,0))),"")) | W24: =IF(OR(TaxOn<>"Yes",NOT(ISNUMBER(M24))),0,IF(IFERROR(INDEX(tt_Tax,MATCH(D24,tt_Type,0)),"No")="Yes",M24,0)) | X24: =IF(T24=1,"",IF(C24="","Missing transaction date",IF(NOT(ISNUMBER(C24)),"Invalid date",IF(OR(C24<DATE(2000,1,1),C24>DATE(2099,12,31)),"Invalid date",IF(D24="","Select a type",IF(U24="","Unknown type: "&D24,IF(V24="","Select an account (Category)",IF(ISNA(MATCH(V24,coa_Name,0)),"Unknown account: "&V24,IF(K24="","Select Paid From / Deposited To",IF(ISNA(MATCH(K24,coa_Name,0)),"Unknown account: "&K24,IF(NOT(ISNUMBER(L24)),"Enter an amount",IF(L24=0,"Enter an amount",IF(ABS(W24)>ABS(L24),"Tax is larger than the amount",""))))))))))))) | Y24: =IF(OR(T24=1,X24<>""),"",IF(AND(B24<>"",COUNTIF(tx_ID,B24)>1),"Duplicate transaction ID",IF(AND(L24<0,D24<>"Adjustment"),"Negative amount — check this entry",IF(AND(D24="Customer Payment",G24=""),"Add the customer",IF(AND(D24="Customer Payment",OR(J24="",COUNTIF(ar_No,J24&"")=0)),"Invoice # in Reference not found on AR sheet",IF(AND(D24="Bill Payment",H24=""),"Add the vendor",IF(AND(D24="Bill Payment",OR(J24="",COUNTIFS(ap_No,J24&"",ap_Party,H24&"")=0)),"Bill # + vendor not found on AP sheet",IF(AND(ISNUMBER(M24),N(M24)<>0,W24=0),"Tax ignored (tax tracking off, or not allowed for this type)",IF(V24=K24&"","Same account on both sides",IF(AND(ISNUMBER(StartDate),C24<StartDate),"Date is before the accounting start date",IF(AND(D24<>"Adjustment",IFERROR(INDEX(coa_Pay,MATCH(K24&"",coa_Name,0)),"")<>"Yes"),"Paid From / Deposited To is not a payment account",""))))))))))) | Z24: =IF(AND(T24=0,X24=""),1,0) | AA24: =IF(Z24=1,IF(U24="In",L24,L24-W24),0) | AB24: =IF(Z24=1,IF(U24="In",L24-W24,L24),0) | AC24: =IF(AND(Z24=1,U24="Out"),W24,0) | AD24: =IF(AND(Z24=1,U24="In"),W24,0)
